Workbook

Sheet Global 1 (1.5)
A1: Scenario 1: Cut extraction by 10% per year, $1 trillion climate grants
A2: Parameters | C2: Initial fossil fuel extraction cap (gigatonnes of CO2e) | D2: Initial carbon charge (per extracted tonne of CO2e) | F2: Running costs of Trust (% of charge money raised) | G2: Initial proportion of charge proceeds going into the Fund (% of total proceeds) | J2: Management costs of the Fund (% of total Fund capital expended) | K2: Assumed annual rate of return on Fund investments | N2: Year that money from distribution pot starts getting reinvested | O2: Distribution costs of the pot (% of total distributed) | P2: Amount of pot to be distributed as climate grants | R2: Initial global population expected in 2025 | S2: Proportion of global population to receive dividends
C3: 37.4 | D3: 144 | F3: 0.005 | G3: 0.05 | J3: 0.0005 | K3: 0.0634 | N3: 2075 | O3: 0.005 | P3: 1300000000000 | S3: 1
C4: Annual shrinkage of cap | D4: Annual growth of charge | G4: Initial annual increase in proportion going into the Fund (% of total proceeds) | H4: After 2035 annual increase in proportion going into the Fund (% of total proceeds) | I4: Starting endowment of the fund | N4: Maximum proportion that gets reinvested | P4: Alternatively, proportion of pot to be distributed as climate grants | S4: Description of segment of population to receive dividends
C5: 0.1 | D5: 0.164 | G5: 0.03 | H5: 0.03 | I5: 0 | N5: 0.1 | P5: 0 | S5: All adults and children worldwide
A7: From start | B7: Year | C7: Carbon cap (gigatonnes of CO2e) | D7: Carbon charge | E7: Amount raised | F7: Amount raised less 0.5% Trust costs | G7: Proportion of this amount going into the Fund | H7: Amount being placed in the Fund this year | I7: Total capital amount that would be in the Fund if there were no management costs | J7: Total capital amount in the Fund less cumulative 0.05% Fund management costs | K7: Investment income of the Fund this year | L7: Amount to be directly distributed (bypassing the Fund) | M7: Total amount in this year's pot for distribution | N7: Amount from distribution pot to go back into Fund for reinvestment | O7: Total distribution pot less 0.5% distribution costs, and less any amount going back to the Fund | P7: Amount to be distributed as climate grants | Q7: Amount left in pot after climate grants distribution | R7: Global population (projected for 1st January each year) | S7: Proportion of global population to receive dividends | T7: Monthly dividend per person
A9: Year 1 | B9: 2025 | C9: =C3 -> 37.4 | D9: =D3 -> 144 | E9: =D9*C9*1000000000 -> 5.3856e+12 | F9: =E9*(1-$F$3) -> 5.358672e+12 | G9: =G3 -> 0.05 | H9: =F9*G9 -> 2.679336e+11 | I9: =$I$5+H9 -> 2.679336e+11 | J9: =($I$5+H9*(1-$J$3)) -> 2.6779963e+11 | K9: =J8*$K$3 -> 0 | L9: =F9*(1-G9) -> 5.0907384e+12 | M9: =K9+L9 -> 5.0907384e+12 | O9: =(M9-N9)*(1-$O$3) -> 5.0652847e+12 | P9: =$P$3 -> 1300000000000 | Q9: =O9-P9 -> 3.7652847e+12 | R9: 8231613070 | S9: =$S$3 -> 1 | T9: =(Q9/(R9*S9))/12 -> 38.118133
A10: Year 2 | B10: 2026 | C10: =C9*(1-$C$5) -> 33.66 | D10: =D9*(1+$D$5) -> 167.616 | E10: =D10*C10*1000000000 -> 5.6419546e+12 | F10: =E10*(1-$F$3) -> 5.6137448e+12 | G10: =$G$3+$G$5 -> 0.08 | H10: =F10*G10 -> 4.4909958e+11 | I10: =I9+H10 -> 7.1703318e+11 | J10: =(J9+H10)*(1-$J$3) -> 7.1654077e+11 | K10: =J9*$K$3 -> 1.6978497e+10 | L10: =F10*(1-G10) -> 5.1646452e+12 | M10: =K10+L10 -> 5.1816237e+12 | O10: =(M10-N10)*(1-$O$3) -> 5.1557156e+12 | P10: =$P$3 -> 1300000000000 | Q10: =O10-P10 -> 3.8557156e+12 | R10: 8300678395 | S10: =$S$3 -> 1 | T10: =(Q10/(R10*S10))/12 -> 38.70884
A11: Year 3 | B11: 2027 | C11: =C10*(1-$C$5) -> 30.294 | D11: =D10*(1+$D$5) -> 195.10502 | E11: =D11*C11*1000000000 -> 5.9105116e+12 | F11: =E11*(1-$F$3) -> 5.880959e+12 | G11: =G10+$G$5 -> 0.11 | H11: =F11*G11 -> 6.4690549e+11 | I11: =I10+H11 -> 1.3639387e+12 | J11: =(J10+H11)*(1-$J$3) -> 1.3627645e+12 | K11: =J10*$K$3 -> 4.5428685e+10 | L11: =F11*(1-G11) -> 5.2340535e+12 | M11: =K11+L11 -> 5.2794822e+12 | O11: =(M11-N11)*(1-$O$3) -> 5.2530848e+12 | P11: =$P$3 -> 1300000000000 | Q11: =O11-P11 -> 3.9530848e+12 | R11: 8369094344 | S11: =$S$3 -> 1 | T11: =(Q11/(R11*S11))/12 -> 39.361933
A12: Year 4 | B12: 2028 | C12: =C11*(1-$C$5) -> 27.2646 | D12: =D11*(1+$D$5) -> 227.10225 | E12: =D12*C12*1000000000 -> 6.1918519e+12 | F12: =E12*(1-$F$3) -> 6.1608927e+12 | G12: =G11+$G$5 -> 0.14 | H12: =F12*G12 -> 8.6252498e+11 | I12: =I11+H12 -> 2.2264637e+12 | J12: =(J11+H12)*(1-$J$3) -> 2.2241769e+12 | K12: =J11*$K$3 -> 8.6399272e+10 | L12: =F12*(1-G12) -> 5.2983677e+12 | M12: =K12+L12 -> 5.384767e+12 | O12: =(M12-N12)*(1-$O$3) -> 5.3578431e+12 | P12: =$P$3 -> 1300000000000 | Q12: =O12-P12 -> 4.0578431e+12 | R12: 8436618886 | S12: =$S$3 -> 1 | T12: =(Q12/(R12*S12))/12 -> 40.081649
A13: Year 5 | B13: 2029 | C13: =C12*(1-$C$5) -> 24.53814 | D13: =D12*(1+$D$5) -> 264.34702 | E13: =D13*C13*1000000000 -> 6.4865841e+12 | F13: =E13*(1-$F$3) -> 6.4541512e+12 | G13: =G12+$G$5 -> 0.17 | H13: =F13*G13 -> 1.0972057e+12 | I13: =I12+H13 -> 3.3236694e+12 | J13: =(J12+H13)*(1-$J$3) -> 3.3197219e+12 | K13: =J12*$K$3 -> 1.4101281e+11 | L13: =F13*(1-G13) -> 5.3569455e+12 | M13: =K13+L13 -> 5.4979583e+12 | O13: =(M13-N13)*(1-$O$3) -> 5.4704685e+12 | P13: =$P$3 -> 1300000000000 | Q13: =O13-P13 -> 4.1704685e+12 | R13: 8503285323 | S13: =$S$3 -> 1 | T13: =(Q13/(R13*S13))/12 -> 40.871149
A14: Year 6 | B14: 2030 | C14: =C13*(1-$C$5) -> 22.084326 | D14: =D13*(1+$D$5) -> 307.69993 | E14: =D14*C14*1000000000 -> 6.7953455e+12 | F14: =E14*(1-$F$3) -> 6.7613688e+12 | G14: =G13+$G$5 -> 0.2 | H14: =F14*G14 -> 1.3522738e+12 | I14: =I13+H14 -> 4.6759431e+12 | J14: =(J13+H14)*(1-$J$3) -> 4.6696596e+12 | K14: =J13*$K$3 -> 2.1047037e+11 | L14: =F14*(1-G14) -> 5.409095e+12 | M14: =K14+L14 -> 5.6195654e+12 | O14: =(M14-N14)*(1-$O$3) -> 5.5914676e+12 | P14: =$P$3 -> 1300000000000 | Q14: =O14-P14 -> 4.2914676e+12 | R14: 8569124911 | S14: =$S$3 -> 1 | T14: =(Q14/(R14*S14))/12 -> 41.733818
A15: Year 7 | B15: 2031 | C15: =C14*(1-$C$5) -> 19.875893 | D15: =D14*(1+$D$5) -> 358.16272 | E15: =D15*C15*1000000000 -> 7.118804e+12 | F15: =E15*(1-$F$3) -> 7.0832099e+12 | G15: =G14+$G$5 -> 0.23 | H15: =F15*G15 -> 1.6291383e+12 | I15: =I14+H15 -> 6.3050814e+12 | J15: =(J14+H15)*(1-$J$3) -> 6.2956485e+12 | K15: =J14*$K$3 -> 2.9605642e+11 | L15: =F15*(1-G15) -> 5.4540716e+12 | M15: =K15+L15 -> 5.7501281e+12 | O15: =(M15-N15)*(1-$O$3) -> 5.7213774e+12 | P15: =$P$3 -> 1300000000000 | Q15: =O15-P15 -> 4.4213774e+12 | R15: 8634119333 | S15: =$S$3 -> 1 | T15: =(Q15/(R15*S15))/12 -> 42.673503
A16: Year 8 | B16: 2032 | C16: =C15*(1-$C$5) -> 17.888304 | D16: =D15*(1+$D$5) -> 416.9014 | E16: =D16*C16*1000000000 -> 7.457659e+12 | F16: =E16*(1-$F$3) -> 7.4203707e+12 | G16: =G15+$G$5 -> 0.26 | H16: =F16*G16 -> 1.9292964e+12 | I16: =I15+H16 -> 8.2343778e+12 | J16: =(J15+H16)*(1-$J$3) -> 8.2208324e+12 | K16: =J15*$K$3 -> 3.9914412e+11 | L16: =F16*(1-G16) -> 5.4910743e+12 | M16: =K16+L16 -> 5.8902185e+12 | O16: =(M16-N16)*(1-$O$3) -> 5.8607674e+12 | P16: =$P$3 -> 1300000000000 | Q16: =O16-P16 -> 4.5607674e+12 | R16: 8698229812 | S16: =$S$3 -> 1 | T16: =(Q16/(R16*S16))/12 -> 43.694402
A17: Year 9 | B17: 2033 | C17: =C16*(1-$C$5) -> 16.099474 | D17: =D16*(1+$D$5) -> 485.27323 | E17: =D17*C17*1000000000 -> 7.8126436e+12 | F17: =E17*(1-$F$3) -> 7.7735804e+12 | G17: =G16+$G$5 -> 0.29 | H17: =F17*G17 -> 2.2543383e+12 | I17: =I16+H17 -> 1.0488716e+13 | J17: =(J16+H17)*(1-$J$3) -> 1.0469933e+13 | K17: =J16*$K$3 -> 5.2120078e+11 | L17: =F17*(1-G17) -> 5.5192421e+12 | M17: =K17+L17 -> 6.0404428e+12 | O17: =(M17-N17)*(1-$O$3) -> 6.0102406e+12 | P17: =$P$3 -> 1300000000000 | Q17: =O17-P17 -> 4.7102406e+12 | R17: 8761449081 | S17: =$S$3 -> 1 | T17: =(Q17/(R17*S17))/12 -> 44.800814
A18: Year 10 | B18: 2034 | C18: =C17*(1-$C$5) -> 14.489526 | D18: =D17*(1+$D$5) -> 564.85804 | E18: =D18*C18*1000000000 -> 8.1845254e+12 | F18: =E18*(1-$F$3) -> 8.1436028e+12 | G18: =G17+$G$5 -> 0.32 | H18: =F18*G18 -> 2.6059529e+12 | I18: =I17+H18 -> 1.3094669e+13 | J18: =(J17+H18)*(1-$J$3) -> 1.3069348e+13 | K18: =J17*$K$3 -> 6.6379376e+11 | L18: =F18*(1-G18) -> 5.5376499e+12 | M18: =K18+L18 -> 6.2014437e+12 | O18: =(M18-N18)*(1-$O$3) -> 6.1704364e+12 | P18: =$P$3 -> 1300000000000 | Q18: =O18-P18 -> 4.8704364e+12 | R18: 8823784909 | S18: =$S$3 -> 1 | T18: =(Q18/(R18*S18))/12 -> 45.997235
A19: Year 11 | B19: 2035 | C19: =C18*(1-$C$5) -> 13.040574 | D19: =D18*(1+$D$5) -> 657.49476 | E19: =D19*C19*1000000000 -> 8.5741088e+12 | F19: =E19*(1-$F$3) -> 8.5312383e+12 | G19: =G18+$G$5 -> 0.35 | H19: =F19*G19 -> 2.9859334e+12 | I19: =I18+H19 -> 1.6080602e+13 | J19: =(J18+H19)*(1-$J$3) -> 1.6047254e+13 | K19: =J18*$K$3 -> 8.2859667e+11 | L19: =F19*(1-G19) -> 5.5453049e+12 | M19: =K19+L19 -> 6.3739016e+12 | O19: =(M19-N19)*(1-$O$3) -> 6.3420321e+12 | P19: =$P$3 -> 1300000000000 | Q19: =O19-P19 -> 5.0420321e+12 | R19: 8885210181 | S19: =$S$3 -> 1 | T19: =(Q19/(R19*S19))/12 -> 47.288621
A20: Year 12 | B20: 2036 | C20: =C19*(1-$C$5) -> 11.736516 | D20: =D19*(1+$D$5) -> 765.3239 | E20: =D20*C20*1000000000 -> 8.9822364e+12 | F20: =E20*(1-$F$3) -> 8.9373252e+12 | G20: =G19+$H$5 -> 0.38 | H20: =F20*G20 -> 3.3961836e+12 | I20: =I19+H20 -> 1.9476786e+13 | J20: =(J19+H20)*(1-$J$3) -> 1.9433716e+13 | K20: =J19*$K$3 -> 1.0173959e+12 | L20: =F20*(1-G20) -> 5.5411416e+12 | M20: =K20+L20 -> 6.5585375e+12 | O20: =(M20-N20)*(1-$O$3) -> 6.5257449e+12 | P20: =$P$3 -> 1300000000000 | Q20: =O20-P20 -> 5.2257449e+12 | R20: 8945686614 | S20: =$S$3 -> 1 | T20: =(Q20/(R20*S20))/12 -> 48.680303
A21: Year 13 | B21: 2037 | C21: =C20*(1-$C$5) -> 10.562865 | D21: =D20*(1+$D$5) -> 890.83702 | E21: =D21*C21*1000000000 -> 9.4097909e+12 | F21: =E21*(1-$F$3) -> 9.3627419e+12 | G21: =G20+$H$5 -> 0.41 | H21: =F21*G21 -> 3.8387242e+12 | I21: =I20+H21 -> 2.331551e+13 | J21: =(J20+H21)*(1-$J$3) -> 2.3260804e+13 | K21: =J20*$K$3 -> 1.2320976e+12 | L21: =F21*(1-G21) -> 5.5240177e+12 | M21: =K21+L21 -> 6.7561153e+12 | O21: =(M21-N21)*(1-$O$3) -> 6.7223347e+12 | P21: =$P$3 -> 1300000000000 | Q21: =O21-P21 -> 5.4223347e+12 | R21: 9005152624 | S21: =$S$3 -> 1 | T21: =(Q21/(R21*S21))/12 -> 50.178075
A22: Year 14 | B22: 2038 | C22: =C21*(1-$C$5) -> 9.5065782 | D22: =D21*(1+$D$5) -> 1036.9343 | E22: =D22*C22*1000000000 -> 9.8576969e+12 | F22: =E22*(1-$F$3) -> 9.8084084e+12 | G22: =G21+$H$5 -> 0.44 | H22: =F22*G22 -> 4.3156997e+12 | I22: =I21+H22 -> 2.763121e+13 | J22: =(J21+H22)*(1-$J$3) -> 2.7562715e+13 | K22: =J21*$K$3 -> 1.474735e+12 | L22: =F22*(1-G22) -> 5.4927087e+12 | M22: =K22+L22 -> 6.9674437e+12 | O22: =(M22-N22)*(1-$O$3) -> 6.9326065e+12 | P22: =$P$3 -> 1300000000000 | Q22: =O22-P22 -> 5.6326065e+12 | R22: 9063572926 | S22: =$S$3 -> 1 | T22: =(Q22/(R22*S22))/12 -> 51.787951
A23: Year 15 | B23: 2039 | C23: =C22*(1-$C$5) -> 8.5559204 | D23: =D22*(1+$D$5) -> 1206.9915 | E23: =D23*C23*1000000000 -> 1.0326923e+13 | F23: =E23*(1-$F$3) -> 1.0275289e+13 | G23: =G22+$H$5 -> 0.47 | H23: =F23*G23 -> 4.8293857e+12 | I23: =I22+H23 -> 3.2460596e+13 | J23: =(J22+H23)*(1-$J$3) -> 3.2375905e+13 | K23: =J22*$K$3 -> 1.7474761e+12 | L23: =F23*(1-G23) -> 5.445903e+12 | M23: =K23+L23 -> 7.1933791e+12 | O23: =(M23-N23)*(1-$O$3) -> 7.1574122e+12 | P23: =$P$3 -> 1300000000000 | Q23: =O23-P23 -> 5.8574122e+12 | R23: 9120928380 | S23: =$S$3 -> 1 | T23: =(Q23/(R23*S23))/12 -> 53.516228
A24: Year 16 | B24: 2040 | C24: =C23*(1-$C$5) -> 7.7003283 | D24: =D23*(1+$D$5) -> 1404.9381 | E24: =D24*C24*1000000000 -> 1.0818485e+13 | F24: =E24*(1-$F$3) -> 1.0764392e+13 | G24: =G23+$H$5 -> 0.5 | H24: =F24*G24 -> 5.3821962e+12 | I24: =I23+H24 -> 3.7842792e+13 | J24: =(J23+H24)*(1-$J$3) -> 3.7739222e+13 | K24: =J23*$K$3 -> 2.0526324e+12 | L24: =F24*(1-G24) -> 5.3821962e+12 | M24: =K24+L24 -> 7.4348286e+12 | O24: =(M24-N24)*(1-$O$3) -> 7.3976544e+12 | P24: =$P$3 -> 1300000000000 | Q24: =O24-P24 -> 6.0976544e+12 | R24: 9177190203 | S24: =$S$3 -> 1 | T24: =(Q24/(R24*S24))/12 -> 55.369656
A25: Year 17 | B25: 2041 | C25: =C24*(1-$C$5) -> 6.9302955 | D25: =D24*(1+$D$5) -> 1635.348 | E25: =D25*C25*1000000000 -> 1.1333445e+13 | F25: =E25*(1-$F$3) -> 1.1276777e+13 | G25: =G24+$H$5 -> 0.53 | H25: =F25*G25 -> 5.9766921e+12 | I25: =I24+H25 -> 4.3819484e+13 | J25: =(J24+H25)*(1-$J$3) -> 4.3694056e+13 | K25: =J24*$K$3 -> 2.3926667e+12 | L25: =F25*(1-G25) -> 5.3000854e+12 | M25: =K25+L25 -> 7.6927521e+12 | O25: =(M25-N25)*(1-$O$3) -> 7.6542883e+12 | P25: =$P$3 -> 1300000000000 | Q25: =O25-P25 -> 6.3542883e+12 | R25: 9232281575 | S25: =$S$3 -> 1 | T25: =(Q25/(R25*S25))/12 -> 57.355706
A26: Year 18 | B26: 2042 | C26: =C25*(1-$C$5) -> 6.237266 | D26: =D25*(1+$D$5) -> 1903.545 | E26: =D26*C26*1000000000 -> 1.1872917e+13 | F26: =E26*(1-$F$3) -> 1.1813552e+13 | G26: =G25+$H$5 -> 0.56 | H26: =F26*G26 -> 6.6155892e+12 | I26: =I25+H26 -> 5.0435073e+13 | J26: =(J25+H26)*(1-$J$3) -> 5.028449e+13 | K26: =J25*$K$3 -> 2.7702032e+12 | L26: =F26*(1-G26) -> 5.1979629e+12 | M26: =K26+L26 -> 7.9681661e+12 | O26: =(M26-N26)*(1-$O$3) -> 7.9283252e+12 | P26: =$P$3 -> 1300000000000 | Q26: =O26-P26 -> 6.6283252e+12 | R26: 9286110371 | S26: =$S$3 -> 1 | T26: =(Q26/(R26*S26))/12 -> 59.482433
A27: Year 19 | B27: 2043 | C27: =C26*(1-$C$5) -> 5.6135394 | D27: =D26*(1+$D$5) -> 2215.7264 | E27: =D27*C27*1000000000 -> 1.2438068e+13 | F27: =E27*(1-$F$3) -> 1.2375877e+13 | G27: =G26+$H$5 -> 0.59 | H27: =F27*G27 -> 7.3017675e+12 | I27: =I26+H27 -> 5.7736841e+13 | J27: =(J26+H27)*(1-$J$3) -> 5.7557465e+13 | K27: =J26*$K$3 -> 3.1880367e+12 | L27: =F27*(1-G27) -> 5.0741096e+12 | M27: =K27+L27 -> 8.2621463e+12 | O27: =(M27-N27)*(1-$O$3) -> 8.2208356e+12 | P27: =$P$3 -> 1300000000000 | Q27: =O27-P27 -> 6.9208356e+12 | R27: 9338661314 | S27: =$S$3 -> 1 | T27: =(Q27/(R27*S27))/12 -> 61.75792
A28: Year 20 | B28: 2044 | C28: =C27*(1-$C$5) -> 5.0521854 | D28: =D27*(1+$D$5) -> 2579.1056 | E28: =D28*C28*1000000000 -> 1.303012e+13 | F28: =E28*(1-$F$3) -> 1.2964969e+13 | G28: =G27+$H$5 -> 0.62 | H28: =F28*G28 -> 8.0382807e+12 | I28: =I27+H28 -> 6.5775121e+13 | J28: =(J27+H28)*(1-$J$3) -> 6.5562948e+13 | K28: =J27*$K$3 -> 3.6491433e+12 | L28: =F28*(1-G28) -> 4.9266882e+12 | M28: =K28+L28 -> 8.5758315e+12 | O28: =(M28-N28)*(1-$O$3) -> 8.5329523e+12 | P28: =$P$3 -> 1300000000000 | Q28: =O28-P28 -> 7.2329523e+12 | R28: 9389873693 | S28: =$S$3 -> 1 | T28: =(Q28/(R28*S28))/12 -> 64.191068
A29: Year 21 | B29: 2045 | C29: =C28*(1-$C$5) -> 4.5469669 | D29: 3000 | E29: =D29*C29*1000000000 -> 1.3640901e+13 | F29: =E29*(1-$F$3) -> 1.3572696e+13 | G29: =G28+$H$5 -> 0.65 | H29: =F29*G29 -> 8.8222525e+12 | I29: =I28+H29 -> 7.4597374e+13 | J29: =(J28+H29)*(1-$J$3) -> 7.4348008e+13 | K29: =J28*$K$3 -> 4.1566909e+12 | L29: =F29*(1-G29) -> 4.7504436e+12 | M29: =K29+L29 -> 8.9071345e+12 | O29: =(M29-N29)*(1-$O$3) -> 8.8625989e+12 | P29: =$P$3 -> 1300000000000 | Q29: =O29-P29 -> 7.5625989e+12 | R29: 9439639668 | S29: =$S$3 -> 1 | T29: =(Q29/(R29*S29))/12 -> 66.762778
A30: Year 22 | B30: 2046 | C30: =C29*(1-$C$5) -> 4.0922702 | D30: =D29*(1+$D$5) -> 3492 | E30: =D30*C30*1000000000 -> 1.4290208e+13 | F30: =E30*(1-$F$3) -> 1.4218756e+13 | G30: =G29+$H$5 -> 0.68 | H30: =F30*G30 -> 9.6687544e+12 | I30: =I29+H30 -> 8.4266128e+13 | J30: =(J29+H30)*(1-$J$3) -> 8.3974754e+13 | K30: =J29*$K$3 -> 4.7136637e+12 | L30: =F30*(1-G30) -> 4.5500021e+12 | M30: =K30+L30 -> 9.2636658e+12 | O30: =(M30-N30)*(1-$O$3) -> 9.2173474e+12 | P30: =$P$3 -> 1300000000000 | Q30: =O30-P30 -> 7.9173474e+12 | R30: 9487889604 | S30: =$S$3 -> 1 | T30: =(Q30/(R30*S30))/12 -> 69.539063
A31: Year 23 | B31: 2047 | C31: =C30*(1-$C$5) -> 3.6830432 | D31: 4000 | E31: =D31*C31*1000000000 -> 1.4732173e+13 | F31: =E31*(1-$F$3) -> 1.4658512e+13 | G31: =G30+$H$5 -> 0.71 | H31: =F31*G31 -> 1.0407543e+13 | I31: =I30+H31 -> 9.4673672e+13 | J31: =(J30+H31)*(1-$J$3) -> 9.4335106e+13 | K31: =J30*$K$3 -> 5.3239994e+12 | L31: =F31*(1-G31) -> 4.2509684e+12 | M31: =K31+L31 -> 9.5749678e+12 | O31: =(M31-N31)*(1-$O$3) -> 9.527093e+12 | P31: =$P$3 -> 1300000000000 | Q31: =O31-P31 -> 8.227093e+12 | R31: 9534545977 | S31: =$S$3 -> 1 | T31: =(Q31/(R31*S31))/12 -> 71.906002
A32: Year 24 | B32: 2048 | C32: =C31*(1-$C$5) -> 3.3147389 | D32: 4000 | E32: =D32*C32*1000000000 -> 1.3258955e+13 | F32: =E32*(1-$F$3) -> 1.3192661e+13 | G32: =G31+$H$5 -> 0.74 | H32: =F32*G32 -> 9.7625689e+12 | I32: =I31+H32 -> 1.0443624e+14 | J32: =(J31+H32)*(1-$J$3) -> 1.0404563e+14 | K32: =J31*$K$3 -> 5.9808457e+12 | L32: =F32*(1-G32) -> 3.4300918e+12 | M32: =K32+L32 -> 9.4109375e+12 | O32: =(M32-N32)*(1-$O$3) -> 9.3638828e+12 | P32: =$P$3 -> 1300000000000 | Q32: =O32-P32 -> 8.0638828e+12 | R32: 9579536043 | S32: =$S$3 -> 1 | T32: =(Q32/(R32*S32))/12 -> 70.148516
A33: Year 25 | B33: 2049 | C33: =C32*(1-$C$5) -> 2.983265 | D33: 4000 | E33: =D33*C33*1000000000 -> 1.193306e+13 | F33: =E33*(1-$F$3) -> 1.1873395e+13 | G33: =G32+$H$5 -> 0.77 | H33: =F33*G33 -> 9.1425138e+12 | I33: =I32+H33 -> 1.1357875e+14 | J33: =(J32+H33)*(1-$J$3) -> 1.1313155e+14 | K33: =J32*$K$3 -> 6.5964927e+12 | L33: =F33*(1-G33) -> 2.7308808e+12 | M33: =K33+L33 -> 9.3273734e+12 | O33: =(M33-N33)*(1-$O$3) -> 9.2807366e+12 | P33: =$P$3 -> 1300000000000 | Q33: =O33-P33 -> 7.9807366e+12 | R33: 9622824029 | S33: =$S$3 -> 1 | T33: =(Q33/(R33*S33))/12 -> 69.112911
A34: Year 26 | B34: 2050 | C34: =C33*(1-$C$5) -> 2.6849385 | D34: 4000 | E34: =D34*C34*1000000000 -> 1.0739754e+13 | F34: =E34*(1-$F$3) -> 1.0686055e+13 | G34: =G33+$H$5 -> 0.8 | H34: =F34*G34 -> 8.5488441e+12 | I34: =I33+H34 -> 1.221276e+14 | J34: =(J33+H34)*(1-$J$3) -> 1.2161955e+14 | K34: =J33*$K$3 -> 7.17254e+12 | L34: =F34*(1-G34) -> 2.137211e+12 | M34: =K34+L34 -> 9.309751e+12 | O34: =(M34-N34)*(1-$O$3) -> 9.2632023e+12 | P34: =$P$3 -> 1300000000000 | Q34: =O34-P34 -> 7.9632023e+12 | R34: 9664378587 | S34: =$S$3 -> 1 | T34: =(Q34/(R34*S34))/12 -> 68.664548
A35: Year 27 | B35: 2051 | C35: =C34*(1-$C$5) -> 2.4164446 | D35: 4000 | E35: =D35*C35*1000000000 -> 9.6657785e+12 | F35: =E35*(1-$F$3) -> 9.6174496e+12 | G35: =G34+$H$5 -> 0.83 | H35: =F35*G35 -> 7.9824832e+12 | I35: =I34+H35 -> 1.3011008e+14 | J35: =(J34+H35)*(1-$J$3) -> 1.2953723e+14 | K35: =J34*$K$3 -> 7.7106794e+12 | L35: =F35*(1-G35) -> 1.6349664e+12 | M35: =K35+L35 -> 9.3456459e+12 | O35: =(M35-N35)*(1-$O$3) -> 9.2989176e+12 | P35: =$P$3 -> 1300000000000 | Q35: =O35-P35 -> 7.9989176e+12 | R35: 9704192304 | S35: =$S$3 -> 1 | T35: =(Q35/(R35*S35))/12 -> 68.689536
A36: Year 28 | B36: 2052 | C36: =C35*(1-$C$5) -> 2.1748002 | D36: 4000 | E36: =D36*C36*1000000000 -> 8.6992007e+12 | F36: =E36*(1-$F$3) -> 8.6557047e+12 | G36: =G35+$H$5 -> 0.86 | H36: =F36*G36 -> 7.443906e+12 | I36: =I35+H36 -> 1.3755399e+14 | J36: =(J35+H36)*(1-$J$3) -> 1.3691265e+14 | K36: =J35*$K$3 -> 8.2126605e+12 | L36: =F36*(1-G36) -> 1.2117987e+12 | M36: =K36+L36 -> 9.4244591e+12 | O36: =(M36-N36)*(1-$O$3) -> 9.3773368e+12 | P36: =$P$3 -> 1300000000000 | Q36: =O36-P36 -> 8.0773368e+12 | R36: 9742264515 | S36: =$S$3 -> 1 | T36: =(Q36/(R36*S36))/12 -> 69.091883
A37: Year 29 | B37: 2053 | C37: =C36*(1-$C$5) -> 1.9573201 | D37: 4000 | E37: =D37*C37*1000000000 -> 7.8292806e+12 | F37: =E37*(1-$F$3) -> 7.7901342e+12 | G37: =G36+$H$5 -> 0.89 | H37: =F37*G37 -> 6.9332194e+12 | I37: =I36+H37 -> 1.4448721e+14 | J37: =(J36+H37)*(1-$J$3) -> 1.4377394e+14 | K37: =J36*$K$3 -> 8.6802618e+12 | L37: =F37*(1-G37) -> 8.5691476e+11 | M37: =K37+L37 -> 9.5371766e+12 | O37: =(M37-N37)*(1-$O$3) -> 9.4894907e+12 | P37: =$P$3 -> 1300000000000 | Q37: =O37-P37 -> 8.1894907e+12 | R37: 9778614614 | S37: =$S$3 -> 1 | T37: =(Q37/(R37*S37))/12 -> 69.790823
A38: Year 30 | B38: 2054 | C38: =C37*(1-$C$5) -> 1.7615881 | D38: 4000 | E38: =D38*C38*1000000000 -> 7.0463525e+12 | F38: =E38*(1-$F$3) -> 7.0111208e+12 | G38: =G37+$H$5 -> 0.92 | H38: =F38*G38 -> 6.4502311e+12 | I38: =I37+H38 -> 1.5093744e+14 | J38: =(J37+H38)*(1-$J$3) -> 1.5014906e+14 | K38: =J37*$K$3 -> 9.115268e+12 | L38: =F38*(1-G38) -> 5.6088966e+11 | M38: =K38+L38 -> 9.6761577e+12 | O38: =(M38-N38)*(1-$O$3) -> 9.6277769e+12 | P38: =$P$3 -> 1300000000000 | Q38: =O38-P38 -> 8.3277769e+12 | R38: 9813251659 | S38: =$S$3 -> 1 | T38: =(Q38/(R38*S38))/12 -> 70.718803
A39: Year 31 | B39: 2055 | C39: =C38*(1-$C$5) -> 1.5854293 | D39: 4000 | E39: =D39*C39*1000000000 -> 6.3417173e+12 | F39: =E39*(1-$F$3) -> 6.3100087e+12 | G39: =G38+$H$5 -> 0.95 | H39: =F39*G39 -> 5.9945083e+12 | I39: =I38+H39 -> 1.5693195e+14 | J39: =(J38+H39)*(1-$J$3) -> 1.560655e+14 | K39: =J38*$K$3 -> 9.5194506e+12 | L39: =F39*(1-G39) -> 3.1550043e+11 | M39: =K39+L39 -> 9.834951e+12 | O39: =(M39-N39)*(1-$O$3) -> 9.7857763e+12 | P39: =$P$3 -> 1300000000000 | Q39: =O39-P39 -> 8.4857763e+12 | R39: 9846237570 | S39: =$S$3 -> 1 | T39: =(Q39/(R39*S39))/12 -> 71.81911
A40: Year 32 | B40: 2056 | C40: =C39*(1-$C$5) -> 1.4268864 | D40: 4000 | E40: =D40*C40*1000000000 -> 5.7075456e+12 | F40: =E40*(1-$F$3) -> 5.6790078e+12 | G40: =G39+$H$5 -> 0.98 | H40: =F40*G40 -> 5.5654277e+12 | I40: =I39+H40 -> 1.6249737e+14 | J40: =(J39+H40)*(1-$J$3) -> 1.6155011e+14 | K40: =J39*$K$3 -> 9.8945526e+12 | L40: =F40*(1-G40) -> 1.1358016e+11 | M40: =K40+L40 -> 1.0008133e+13 | O40: =(M40-N40)*(1-$O$3) -> 9.9580921e+12 | P40: =$P$3 -> 1300000000000 | Q40: =O40-P40 -> 8.6580921e+12 | R40: 9877680392 | S40: =$S$3 -> 1 | T40: =(Q40/(R40*S40))/12 -> 73.044242
A41: Year 33 | B41: 2057 | C41: =C40*(1-$C$5) -> 1.2841977 | D41: 4000 | E41: =D41*C41*1000000000 -> 5.136791e+12 | F41: =E41*(1-$F$3) -> 5.111107e+12 | G41: 1 | H41: =F41*G41 -> 5.111107e+12 | I41: =I40+H41 -> 1.6760848e+14 | J41: =(J40+H41)*(1-$J$3) -> 1.6657789e+14 | K41: =J40*$K$3 -> 1.0242277e+13 | L41: =F41*(1-G41) -> 0 | M41: =K41+L41 -> 1.0242277e+13 | N41: =M41*0.2% -> 2.0484554e+10 | O41: =(M41-N41)*(1-$O$3) -> 1.0170684e+13 | P41: =$P$3 -> 1300000000000 | Q41: =O41-P41 -> 8.8706835e+12 | R41: 9907637193 | S41: =$S$3 -> 1 | T41: =(Q41/(R41*S41))/12 -> 74.611496
A42: Year 34 | B42: 2058 | C42: =C41*(1-$C$5) -> 1.155778 | D42: 4000 | E42: =D42*C42*1000000000 -> 4.6231119e+12 | F42: =E42*(1-$F$3) -> 4.5999963e+12 | G42: 1 | H42: =F42*G42 -> 4.5999963e+12 | I42: =I41+H42 -> 1.7220848e+14 | J42: =(J41+H42)*(1-$J$3) -> 1.710923e+14 | K42: =J41*$K$3 -> 1.0561038e+13 | L42: =F42*(1-G42) -> 0 | M42: =K42+L42 -> 1.0561038e+13 | N42: =M42*0.4% -> 4.2244152e+10 | O42: =(M42-N42)*(1-$O$3) -> 1.04662e+13 | P42: =$P$3 -> 1300000000000 | Q42: =O42-P42 -> 9.1662e+12 | R42: 9936164379 | S42: =$S$3 -> 1 | T42: =(Q42/(R42*S42))/12 -> 76.875741
...

Sheet Global 2 (1.6)
A1: Scenario 1: Cut extraction by 10% per year, $1 trillion climate grants
A2: Parameters | C2: Initial fossil fuel extraction cap (gigatonnes of CO2e) | D2: Initial carbon charge (per extracted tonne of CO2e) | F2: Running costs of Trust (% of charge money raised) | G2: Initial proportion of charge proceeds going into the Fund (% of total proceeds) | J2: Management costs of the Fund (% of total Fund capital expended) | K2: Assumed annual rate of return on Fund investments | N2: Year that money from distribution pot starts getting reinvested | O2: Distribution costs of the pot (% of total distributed) | P2: Amount of pot to be distributed as climate grants | R2: Initial global population expected in 2025 | S2: Proportion of global population to receive dividends
C3: 37.4 | D3: 144 | F3: 0.005 | G3: 0.1 | J3: 0.0005 | K3: 0.0634 | N3: 2075 | O3: 0.005 | P3: 1300000000000 | S3: 1
C4: Annual shrinkage of cap | D4: Annual growth of charge | G4: Initial annual increase in proportion going into the Fund (% of total proceeds) | H4: After 2035 annual increase in proportion going into the Fund (% of total proceeds) | I4: Starting endowment of the fund | N4: Maximum proportion that gets reinvested | P4: Alternatively, proportion of pot to be distributed as climate grants | S4: Description of segment of population to receive dividends
C5: 0.1 | D5: 0.164 | G5: 0.02 | H5: 0.02 | I5: 0 | N5: 0.1 | P5: 0 | S5: All adults and children worldwide
A7: From start | B7: Year | C7: Carbon cap (gigatonnes of CO2e) | D7: Carbon charge | E7: Amount raised | F7: Amount raised less 0.5% Trust costs | G7: Proportion of this amount going into the Fund | H7: Amount being placed in the Fund this year | I7: Total capital amount that would be in the Fund if there were no management costs | J7: Total capital amount in the Fund less cumulative 0.05% Fund management costs | K7: Investment income of the Fund this year | L7: Amount to be directly distributed (bypassing the Fund) | M7: Total amount in this year's pot for distribution | N7: Amount from distribution pot to go back into Fund for reinvestment | O7: Total distribution pot less 0.5% distribution costs, and less any amount going back to the Fund | P7: Amount to be distributed as climate grants | Q7: Amount left in pot after climate grants distribution | R7: Global population (projected for 1st January each year) | S7: Proportion of global population to receive dividends | T7: Monthly dividend per person
A9: Year 1 | B9: 2025 | C9: =C3 -> 37.4 | D9: =D3 -> 144 | E9: =D9*C9*1000000000 -> 5.3856e+12 | F9: =E9*(1-$F$3) -> 5.358672e+12 | G9: 0.1 | H9: =F9*G9 -> 5.358672e+11 | I9: =$I$5+H9 -> 5.358672e+11 | J9: =($I$5+H9*(1-$J$3)) -> 5.3559927e+11 | K9: =J8*$K$3 -> 0 | L9: =F9*(1-G9) -> 4.8228048e+12 | M9: =K9+L9 -> 4.8228048e+12 | O9: =(M9-N9)*(1-$O$3) -> 4.7986908e+12 | P9: =$P$3 -> 1300000000000 | Q9: =O9-P9 -> 3.4986908e+12 | R9: 8231613070 | S9: =$S$3 -> 1 | T9: =(Q9/(R9*S9))/12 -> 35.41925
A10: Year 2 | B10: 2026 | C10: =C9*(1-$C$5) -> 33.66 | D10: =D9*(1+$D$5) -> 167.616 | E10: =D10*C10*1000000000 -> 5.6419546e+12 | F10: =E10*(1-$F$3) -> 5.6137448e+12 | G10: 0.12 | H10: =F10*G10 -> 6.7364937e+11 | I10: =I9+H10 -> 1.2095166e+12 | J10: =(J9+H10)*(1-$J$3) -> 1.208644e+12 | K10: =J9*$K$3 -> 3.3956993e+10 | L10: =F10*(1-G10) -> 4.9400954e+12 | M10: =K10+L10 -> 4.9740524e+12 | O10: =(M10-N10)*(1-$O$3) -> 4.9491821e+12 | P10: =$P$3 -> 1300000000000 | Q10: =O10-P10 -> 3.6491821e+12 | R10: 8300678395 | S10: =$S$3 -> 1 | T10: =(Q10/(R10*S10))/12 -> 36.635381
A11: Year 3 | B11: 2027 | C11: =C10*(1-$C$5) -> 30.294 | D11: =D10*(1+$D$5) -> 195.10502 | E11: =D11*C11*1000000000 -> 5.9105116e+12 | F11: =E11*(1-$F$3) -> 5.880959e+12 | G11: =G10+$G$5 -> 0.14 | H11: =F11*G11 -> 8.2333427e+11 | I11: =I10+H11 -> 2.0328508e+12 | J11: =(J10+H11)*(1-$J$3) -> 2.0309623e+12 | K11: =J10*$K$3 -> 7.6628031e+10 | L11: =F11*(1-G11) -> 5.0576248e+12 | M11: =K11+L11 -> 5.1342528e+12 | O11: =(M11-N11)*(1-$O$3) -> 5.1085815e+12 | P11: =$P$3 -> 1300000000000 | Q11: =O11-P11 -> 3.8085815e+12 | R11: 8369094344 | S11: =$S$3 -> 1 | T11: =(Q11/(R11*S11))/12 -> 37.923075
A12: Year 4 | B12: 2028 | C12: =C11*(1-$C$5) -> 27.2646 | D12: =D11*(1+$D$5) -> 227.10225 | E12: =D12*C12*1000000000 -> 6.1918519e+12 | F12: =E12*(1-$F$3) -> 6.1608927e+12 | G12: =G11+$G$5 -> 0.16 | H12: =F12*G12 -> 9.8574283e+11 | I12: =I11+H12 -> 3.0185937e+12 | J12: =(J11+H12)*(1-$J$3) -> 3.0151968e+12 | K12: =J11*$K$3 -> 1.2876301e+11 | L12: =F12*(1-G12) -> 5.1751499e+12 | M12: =K12+L12 -> 5.3039129e+12 | O12: =(M12-N12)*(1-$O$3) -> 5.2773933e+12 | P12: =$P$3 -> 1300000000000 | Q12: =O12-P12 -> 3.9773933e+12 | R12: 8436618886 | S12: =$S$3 -> 1 | T12: =(Q12/(R12*S12))/12 -> 39.287
A13: Year 5 | B13: 2029 | C13: =C12*(1-$C$5) -> 24.53814 | D13: =D12*(1+$D$5) -> 264.34702 | E13: =D13*C13*1000000000 -> 6.4865841e+12 | F13: =E13*(1-$F$3) -> 6.4541512e+12 | G13: =G12+$G$5 -> 0.18 | H13: =F13*G13 -> 1.1617472e+12 | I13: =I12+H13 -> 4.1803409e+12 | J13: =(J12+H13)*(1-$J$3) -> 4.1748555e+12 | K13: =J12*$K$3 -> 1.9116348e+11 | L13: =F13*(1-G13) -> 5.292404e+12 | M13: =K13+L13 -> 5.4835674e+12 | O13: =(M13-N13)*(1-$O$3) -> 5.4561496e+12 | P13: =$P$3 -> 1300000000000 | Q13: =O13-P13 -> 4.1561496e+12 | R13: 8503285323 | S13: =$S$3 -> 1 | T13: =(Q13/(R13*S13))/12 -> 40.730822
A14: Year 6 | B14: 2030 | C14: =C13*(1-$C$5) -> 22.084326 | D14: =D13*(1+$D$5) -> 307.69993 | E14: =D14*C14*1000000000 -> 6.7953455e+12 | F14: =E14*(1-$F$3) -> 6.7613688e+12 | G14: =G13+$G$5 -> 0.2 | H14: =F14*G14 -> 1.3522738e+12 | I14: =I13+H14 -> 5.5326146e+12 | J14: =(J13+H14)*(1-$J$3) -> 5.5243657e+12 | K14: =J13*$K$3 -> 2.6468584e+11 | L14: =F14*(1-G14) -> 5.409095e+12 | M14: =K14+L14 -> 5.6737809e+12 | O14: =(M14-N14)*(1-$O$3) -> 5.645412e+12 | P14: =$P$3 -> 1300000000000 | Q14: =O14-P14 -> 4.345412e+12 | R14: 8569124911 | S14: =$S$3 -> 1 | T14: =(Q14/(R14*S14))/12 -> 42.258418
A15: Year 7 | B15: 2031 | C15: =C14*(1-$C$5) -> 19.875893 | D15: =D14*(1+$D$5) -> 358.16272 | E15: =D15*C15*1000000000 -> 7.118804e+12 | F15: =E15*(1-$F$3) -> 7.0832099e+12 | G15: =G14+$G$5 -> 0.22 | H15: =F15*G15 -> 1.5583062e+12 | I15: =I14+H15 -> 7.0909208e+12 | J15: =(J14+H15)*(1-$J$3) -> 7.0791306e+12 | K15: =J14*$K$3 -> 3.5024479e+11 | L15: =F15*(1-G15) -> 5.5249037e+12 | M15: =K15+L15 -> 5.8751485e+12 | O15: =(M15-N15)*(1-$O$3) -> 5.8457728e+12 | P15: =$P$3 -> 1300000000000 | Q15: =O15-P15 -> 4.5457728e+12 | R15: 8634119333 | S15: =$S$3 -> 1 | T15: =(Q15/(R15*S15))/12 -> 43.874121
A16: Year 8 | B16: 2032 | C16: =C15*(1-$C$5) -> 17.888304 | D16: =D15*(1+$D$5) -> 416.9014 | E16: =D16*C16*1000000000 -> 7.457659e+12 | F16: =E16*(1-$F$3) -> 7.4203707e+12 | G16: =G15+$G$5 -> 0.24 | H16: =F16*G16 -> 1.780889e+12 | I16: =I15+H16 -> 8.8718098e+12 | J16: =(J15+H16)*(1-$J$3) -> 8.8555895e+12 | K16: =J15*$K$3 -> 4.4881688e+11 | L16: =F16*(1-G16) -> 5.6394818e+12 | M16: =K16+L16 -> 6.0882986e+12 | O16: =(M16-N16)*(1-$O$3) -> 6.0578571e+12 | P16: =$P$3 -> 1300000000000 | Q16: =O16-P16 -> 4.7578571e+12 | R16: 8698229812 | S16: =$S$3 -> 1 | T16: =(Q16/(R16*S16))/12 -> 45.582619
A17: Year 9 | B17: 2033 | C17: =C16*(1-$C$5) -> 16.099474 | D17: =D16*(1+$D$5) -> 485.27323 | E17: =D17*C17*1000000000 -> 7.8126436e+12 | F17: =E17*(1-$F$3) -> 7.7735804e+12 | G17: =G16+$G$5 -> 0.26 | H17: =F17*G17 -> 2.0211309e+12 | I17: =I16+H17 -> 1.0892941e+13 | J17: =(J16+H17)*(1-$J$3) -> 1.0871282e+13 | K17: =J16*$K$3 -> 5.6144438e+11 | L17: =F17*(1-G17) -> 5.7524495e+12 | M17: =K17+L17 -> 6.3138938e+12 | O17: =(M17-N17)*(1-$O$3) -> 6.2823244e+12 | P17: =$P$3 -> 1300000000000 | Q17: =O17-P17 -> 4.9823244e+12 | R17: 8761449081 | S17: =$S$3 -> 1 | T17: =(Q17/(R17*S17))/12 -> 47.388702
A18: Year 10 | B18: 2034 | C18: =C17*(1-$C$5) -> 14.489526 | D18: =D17*(1+$D$5) -> 564.85804 | E18: =D18*C18*1000000000 -> 8.1845254e+12 | F18: =E18*(1-$F$3) -> 8.1436028e+12 | G18: =G17+$G$5 -> 0.28 | H18: =F18*G18 -> 2.2802088e+12 | I18: =I17+H18 -> 1.3173149e+13 | J18: =(J17+H18)*(1-$J$3) -> 1.3144915e+13 | K18: =J17*$K$3 -> 6.8923928e+11 | L18: =F18*(1-G18) -> 5.863394e+12 | M18: =K18+L18 -> 6.5526333e+12 | O18: =(M18-N18)*(1-$O$3) -> 6.5198701e+12 | P18: =$P$3 -> 1300000000000 | Q18: =O18-P18 -> 5.2198701e+12 | R18: 8823784909 | S18: =$S$3 -> 1 | T18: =(Q18/(R18*S18))/12 -> 49.297346
A19: Year 11 | B19: 2035 | C19: =C18*(1-$C$5) -> 13.040574 | D19: =D18*(1+$D$5) -> 657.49476 | E19: =D19*C19*1000000000 -> 8.5741088e+12 | F19: =E19*(1-$F$3) -> 8.5312383e+12 | G19: =G18+$G$5 -> 0.3 | H19: =F19*G19 -> 2.5593715e+12 | I19: =I18+H19 -> 1.5732521e+13 | J19: =(J18+H19)*(1-$J$3) -> 1.5696434e+13 | K19: =J18*$K$3 -> 8.3338762e+11 | L19: =F19*(1-G19) -> 5.9718668e+12 | M19: =K19+L19 -> 6.8052544e+12 | O19: =(M19-N19)*(1-$O$3) -> 6.7712281e+12 | P19: =$P$3 -> 1300000000000 | Q19: =O19-P19 -> 5.4712281e+12 | R19: 8885210181 | S19: =$S$3 -> 1 | T19: =(Q19/(R19*S19))/12 -> 51.314
A20: Year 12 | B20: 2036 | C20: =C19*(1-$C$5) -> 11.736516 | D20: =D19*(1+$D$5) -> 765.3239 | E20: =D20*C20*1000000000 -> 8.9822364e+12 | F20: =E20*(1-$F$3) -> 8.9373252e+12 | G20: 0.33 | H20: =F20*G20 -> 2.9493173e+12 | I20: =I19+H20 -> 1.8681838e+13 | J20: =(J19+H20)*(1-$J$3) -> 1.8636429e+13 | K20: =J19*$K$3 -> 9.9515394e+11 | L20: =F20*(1-G20) -> 5.9880079e+12 | M20: =K20+L20 -> 6.9831618e+12 | O20: =(M20-N20)*(1-$O$3) -> 6.948246e+12 | P20: =$P$3 -> 1300000000000 | Q20: =O20-P20 -> 5.648246e+12 | R20: 8945686614 | S20: =$S$3 -> 1 | T20: =(Q20/(R20*S20))/12 -> 52.616103
A21: Year 13 | B21: 2037 | C21: =C20*(1-$C$5) -> 10.562865 | D21: =D20*(1+$D$5) -> 890.83702 | E21: =D21*C21*1000000000 -> 9.4097909e+12 | F21: =E21*(1-$F$3) -> 9.3627419e+12 | G21: =G20+$H$5 -> 0.35 | H21: =F21*G21 -> 3.2769597e+12 | I21: =I20+H21 -> 2.1958798e+13 | J21: =(J20+H21)*(1-$J$3) -> 2.1902432e+13 | K21: =J20*$K$3 -> 1.1815496e+12 | L21: =F21*(1-G21) -> 6.0857822e+12 | M21: =K21+L21 -> 7.2673318e+12 | O21: =(M21-N21)*(1-$O$3) -> 7.2309952e+12 | P21: =$P$3 -> 1300000000000 | Q21: =O21-P21 -> 5.9309952e+12 | R21: 9005152624 | S21: =$S$3 -> 1 | T21: =(Q21/(R21*S21))/12 -> 54.885199
A22: Year 14 | B22: 2038 | C22: =C21*(1-$C$5) -> 9.5065782 | D22: =D21*(1+$D$5) -> 1036.9343 | E22: =D22*C22*1000000000 -> 9.8576969e+12 | F22: =E22*(1-$F$3) -> 9.8084084e+12 | G22: =G21+$H$5 -> 0.37 | H22: =F22*G22 -> 3.6291111e+12 | I22: =I21+H22 -> 2.5587909e+13 | J22: =(J21+H22)*(1-$J$3) -> 2.5518777e+13 | K22: =J21*$K$3 -> 1.3886142e+12 | L22: =F22*(1-G22) -> 6.1792973e+12 | M22: =K22+L22 -> 7.5679115e+12 | O22: =(M22-N22)*(1-$O$3) -> 7.5300719e+12 | P22: =$P$3 -> 1300000000000 | Q22: =O22-P22 -> 6.2300719e+12 | R22: 9063572926 | S22: =$S$3 -> 1 | T22: =(Q22/(R22*S22))/12 -> 57.281236
A23: Year 15 | B23: 2039 | C23: =C22*(1-$C$5) -> 8.5559204 | D23: =D22*(1+$D$5) -> 1206.9915 | E23: =D23*C23*1000000000 -> 1.0326923e+13 | F23: =E23*(1-$F$3) -> 1.0275289e+13 | G23: =G22+$H$5 -> 0.39 | H23: =F23*G23 -> 4.0073626e+12 | I23: =I22+H23 -> 2.9595272e+13 | J23: =(J22+H23)*(1-$J$3) -> 2.9511377e+13 | K23: =J22*$K$3 -> 1.6178905e+12 | L23: =F23*(1-G23) -> 6.2679261e+12 | M23: =K23+L23 -> 7.8858166e+12 | O23: =(M23-N23)*(1-$O$3) -> 7.8463875e+12 | P23: =$P$3 -> 1300000000000 | Q23: =O23-P23 -> 6.5463875e+12 | R23: 9120928380 | S23: =$S$3 -> 1 | T23: =(Q23/(R23*S23))/12 -> 59.811049
A24: Year 16 | B24: 2040 | C24: =C23*(1-$C$5) -> 7.7003283 | D24: =D23*(1+$D$5) -> 1404.9381 | E24: =D24*C24*1000000000 -> 1.0818485e+13 | F24: =E24*(1-$F$3) -> 1.0764392e+13 | G24: =G23+$H$5 -> 0.41 | H24: =F24*G24 -> 4.4134009e+12 | I24: =I23+H24 -> 3.4008673e+13 | J24: =(J23+H24)*(1-$J$3) -> 3.3907815e+13 | K24: =J23*$K$3 -> 1.8710213e+12 | L24: =F24*(1-G24) -> 6.3509915e+12 | M24: =K24+L24 -> 8.2220128e+12 | O24: =(M24-N24)*(1-$O$3) -> 8.1809027e+12 | P24: =$P$3 -> 1300000000000 | Q24: =O24-P24 -> 6.8809027e+12 | R24: 9177190203 | S24: =$S$3 -> 1 | T24: =(Q24/(R24*S24))/12 -> 62.481931
A25: Year 17 | B25: 2041 | C25: =C24*(1-$C$5) -> 6.9302955 | D25: =D24*(1+$D$5) -> 1635.348 | E25: =D25*C25*1000000000 -> 1.1333445e+13 | F25: =E25*(1-$F$3) -> 1.1276777e+13 | G25: =G24+$H$5 -> 0.43 | H25: =F25*G25 -> 4.8490143e+12 | I25: =I24+H25 -> 3.8857687e+13 | J25: =(J24+H25)*(1-$J$3) -> 3.8737451e+13 | K25: =J24*$K$3 -> 2.1497555e+12 | L25: =F25*(1-G25) -> 6.4277632e+12 | M25: =K25+L25 -> 8.5775187e+12 | O25: =(M25-N25)*(1-$O$3) -> 8.5346311e+12 | P25: =$P$3 -> 1300000000000 | Q25: =O25-P25 -> 7.2346311e+12 | R25: 9232281575 | S25: =$S$3 -> 1 | T25: =(Q25/(R25*S25))/12 -> 65.301943
A26: Year 18 | B26: 2042 | C26: =C25*(1-$C$5) -> 6.237266 | D26: =D25*(1+$D$5) -> 1903.545 | E26: =D26*C26*1000000000 -> 1.1872917e+13 | F26: =E26*(1-$F$3) -> 1.1813552e+13 | G26: =G25+$H$5 -> 0.45 | H26: =F26*G26 -> 5.3160984e+12 | I26: =I25+H26 -> 4.4173785e+13 | J26: =(J25+H26)*(1-$J$3) -> 4.4031523e+13 | K26: =J25*$K$3 -> 2.4559544e+12 | L26: =F26*(1-G26) -> 6.4974537e+12 | M26: =K26+L26 -> 8.9534081e+12 | O26: =(M26-N26)*(1-$O$3) -> 8.908641e+12 | P26: =$P$3 -> 1300000000000 | Q26: =O26-P26 -> 7.608641e+12 | R26: 9286110371 | S26: =$S$3 -> 1 | T26: =(Q26/(R26*S26))/12 -> 68.279763
A27: Year 19 | B27: 2043 | C27: =C26*(1-$C$5) -> 5.6135394 | D27: =D26*(1+$D$5) -> 2215.7264 | E27: =D27*C27*1000000000 -> 1.2438068e+13 | F27: =E27*(1-$F$3) -> 1.2375877e+13 | G27: =G26+$H$5 -> 0.47 | H27: =F27*G27 -> 5.8166623e+12 | I27: =I26+H27 -> 4.9990448e+13 | J27: =(J26+H27)*(1-$J$3) -> 4.9823261e+13 | K27: =J26*$K$3 -> 2.7915985e+12 | L27: =F27*(1-G27) -> 6.5592149e+12 | M27: =K27+L27 -> 9.3508134e+12 | O27: =(M27-N27)*(1-$O$3) -> 9.3040594e+12 | P27: =$P$3 -> 1300000000000 | Q27: =O27-P27 -> 8.0040594e+12 | R27: 9338661314 | S27: =$S$3 -> 1 | T27: =(Q27/(R27*S27))/12 -> 71.424043
A28: Year 20 | B28: 2044 | C28: =C27*(1-$C$5) -> 5.0521854 | D28: =D27*(1+$D$5) -> 2579.1056 | E28: =D28*C28*1000000000 -> 1.303012e+13 | F28: =E28*(1-$F$3) -> 1.2964969e+13 | G28: =G27+$H$5 -> 0.49 | H28: =F28*G28 -> 6.3528348e+12 | I28: =I27+H28 -> 5.6343282e+13 | J28: =(J27+H28)*(1-$J$3) -> 5.6148008e+13 | K28: =J27*$K$3 -> 3.1587947e+12 | L28: =F28*(1-G28) -> 6.6121342e+12 | M28: =K28+L28 -> 9.7709289e+12 | O28: =(M28-N28)*(1-$O$3) -> 9.7220743e+12 | P28: =$P$3 -> 1300000000000 | Q28: =O28-P28 -> 8.4220743e+12 | R28: 9389873693 | S28: =$S$3 -> 1 | T28: =(Q28/(R28*S28))/12 -> 74.744298
A29: Year 21 | B29: 2045 | C29: =C28*(1-$C$5) -> 4.5469669 | D29: 3000 | E29: =D29*C29*1000000000 -> 1.3640901e+13 | F29: =E29*(1-$F$3) -> 1.3572696e+13 | G29: =G28+$H$5 -> 0.51 | H29: =F29*G29 -> 6.922075e+12 | I29: =I28+H29 -> 6.3265357e+13 | J29: =(J28+H29)*(1-$J$3) -> 6.3038548e+13 | K29: =J28*$K$3 -> 3.5597837e+12 | L29: =F29*(1-G29) -> 6.6506211e+12 | M29: =K29+L29 -> 1.0210405e+13 | O29: =(M29-N29)*(1-$O$3) -> 1.0159353e+13 | P29: =$P$3 -> 1300000000000 | Q29: =O29-P29 -> 8.8593528e+12 | R29: 9439639668 | S29: =$S$3 -> 1 | T29: =(Q29/(R29*S29))/12 -> 78.210549
A30: Year 22 | B30: 2046 | C30: =C29*(1-$C$5) -> 4.0922702 | D30: =D29*(1+$D$5) -> 3492 | E30: =D30*C30*1000000000 -> 1.4290208e+13 | F30: =E30*(1-$F$3) -> 1.4218756e+13 | G30: =G29+$H$5 -> 0.53 | H30: =F30*G30 -> 7.5359409e+12 | I30: =I29+H30 -> 7.0801298e+13 | J30: =(J29+H30)*(1-$J$3) -> 7.0539201e+13 | K30: =J29*$K$3 -> 3.9966439e+12 | L30: =F30*(1-G30) -> 6.6828155e+12 | M30: =K30+L30 -> 1.0679459e+13 | O30: =(M30-N30)*(1-$O$3) -> 1.0626062e+13 | P30: =$P$3 -> 1300000000000 | Q30: =O30-P30 -> 9.3260622e+12 | R30: 9487889604 | S30: =$S$3 -> 1 | T30: =(Q30/(R30*S30))/12 -> 81.911983
A31: Year 23 | B31: 2047 | C31: =C30*(1-$C$5) -> 3.6830432 | D31: 4000 | E31: =D31*C31*1000000000 -> 1.4732173e+13 | F31: =E31*(1-$F$3) -> 1.4658512e+13 | G31: =G30+$H$5 -> 0.55 | H31: =F31*G31 -> 8.0621815e+12 | I31: =I30+H31 -> 7.886348e+13 | J31: =(J30+H31)*(1-$J$3) -> 7.8562082e+13 | K31: =J30*$K$3 -> 4.4721854e+12 | L31: =F31*(1-G31) -> 6.5963303e+12 | M31: =K31+L31 -> 1.1068516e+13 | O31: =(M31-N31)*(1-$O$3) -> 1.1013173e+13 | P31: =$P$3 -> 1300000000000 | Q31: =O31-P31 -> 9.7131731e+12 | R31: 9534545977 | S31: =$S$3 -> 1 | T31: =(Q31/(R31*S31))/12 -> 84.894561
A32: Year 24 | B32: 2048 | C32: =C31*(1-$C$5) -> 3.3147389 | D32: 4000 | E32: =D32*C32*1000000000 -> 1.3258955e+13 | F32: =E32*(1-$F$3) -> 1.3192661e+13 | G32: =G31+$H$5 -> 0.57 | H32: =F32*G32 -> 7.5198166e+12 | I32: =I31+H32 -> 8.6383296e+13 | J32: =(J31+H32)*(1-$J$3) -> 8.6038858e+13 | K32: =J31*$K$3 -> 4.980836e+12 | L32: =F32*(1-G32) -> 5.6728441e+12 | M32: =K32+L32 -> 1.065368e+13 | O32: =(M32-N32)*(1-$O$3) -> 1.0600412e+13 | P32: =$P$3 -> 1300000000000 | Q32: =O32-P32 -> 9.3004117e+12 | R32: 9579536043 | S32: =$S$3 -> 1 | T32: =(Q32/(R32*S32))/12 -> 80.905203
A33: Year 25 | B33: 2049 | C33: =C32*(1-$C$5) -> 2.983265 | D33: 4000 | E33: =D33*C33*1000000000 -> 1.193306e+13 | F33: =E33*(1-$F$3) -> 1.1873395e+13 | G33: =G32+$H$5 -> 0.59 | H33: =F33*G33 -> 7.0053028e+12 | I33: =I32+H33 -> 9.3388599e+13 | J33: =(J32+H33)*(1-$J$3) -> 9.2997639e+13 | K33: =J32*$K$3 -> 5.4548636e+12 | L33: =F33*(1-G33) -> 4.8680918e+12 | M33: =K33+L33 -> 1.0322955e+13 | O33: =(M33-N33)*(1-$O$3) -> 1.0271341e+13 | P33: =$P$3 -> 1300000000000 | Q33: =O33-P33 -> 8.9713406e+12 | R33: 9622824029 | S33: =$S$3 -> 1 | T33: =(Q33/(R33*S33))/12 -> 77.691509
A34: Year 26 | B34: 2050 | C34: =C33*(1-$C$5) -> 2.6849385 | D34: 4000 | E34: =D34*C34*1000000000 -> 1.0739754e+13 | F34: =E34*(1-$F$3) -> 1.0686055e+13 | G34: =G33+$H$5 -> 0.61 | H34: =F34*G34 -> 6.5184936e+12 | I34: =I33+H34 -> 9.9907093e+13 | J34: =(J33+H34)*(1-$J$3) -> 9.9466374e+13 | K34: =J33*$K$3 -> 5.8960503e+12 | L34: =F34*(1-G34) -> 4.1675615e+12 | M34: =K34+L34 -> 1.0063612e+13 | O34: =(M34-N34)*(1-$O$3) -> 1.0013294e+13 | P34: =$P$3 -> 1300000000000 | Q34: =O34-P34 -> 8.7132937e+12 | R34: 9664378587 | S34: =$S$3 -> 1 | T34: =(Q34/(R34*S34))/12 -> 75.132385
A35: Year 27 | B35: 2051 | C35: 0.1 | D35: 4000 | E35: =D35*C35*1000000000 -> 400000000000 | F35: =E35*(1-$F$3) -> 398000000000 | G35: =G34+$H$5 -> 0.63 | H35: =F35*G35 -> 2.5074e+11 | I35: =I34+H35 -> 1.0015783e+14 | J35: =(J34+H35)*(1-$J$3) -> 9.9667256e+13 | K35: =J34*$K$3 -> 6.3061681e+12 | L35: =F35*(1-G35) -> 1.4726e+11 | M35: =K35+L35 -> 6.4534281e+12 | O35: =(M35-N35)*(1-$O$3) -> 6.421161e+12 | Q35: =O35-P35 -> 6.421161e+12 | R35: 9704192304 | S35: =$S$3 -> 1 | T35: =(Q35/(R35*S35))/12 -> 55.140782
A36: Year 28 | B36: 2052 | C36: =C35*(1-$C$5) -> 0.09 | D36: 4000 | E36: =D36*C36*1000000000 -> 3.6e+11 | F36: =E36*(1-$F$3) -> 3.582e+11 | G36: =G35+$H$5 -> 0.65 | H36: =F36*G36 -> 2.3283e+11 | I36: =I35+H36 -> 1.0039066e+14 | J36: =(J35+H36)*(1-$J$3) -> 9.9850136e+13 | K36: =J35*$K$3 -> 6.318904e+12 | L36: =F36*(1-G36) -> 1.2537e+11 | M36: =K36+L36 -> 6.444274e+12 | O36: =(M36-N36)*(1-$O$3) -> 6.4120526e+12 | Q36: =O36-P36 -> 6.4120526e+12 | R36: 9742264515 | S36: =$S$3 -> 1 | T36: =(Q36/(R36*S36))/12 -> 54.847384
A37: Year 29 | B37: 2053 | C37: =C36*(1-$C$5) -> 0.081 | D37: 4000 | E37: =D37*C37*1000000000 -> 3.24e+11 | F37: =E37*(1-$F$3) -> 3.2238e+11 | G37: =G36+$H$5 -> 0.67 | H37: =F37*G37 -> 2.159946e+11 | I37: =I36+H37 -> 1.0060666e+14 | J37: =(J36+H37)*(1-$J$3) -> 1.000161e+14 | K37: =J36*$K$3 -> 6.3304986e+12 | L37: =F37*(1-G37) -> 1.063854e+11 | M37: =K37+L37 -> 6.436884e+12 | O37: =(M37-N37)*(1-$O$3) -> 6.4046996e+12 | Q37: =O37-P37 -> 6.4046996e+12 | R37: 9778614614 | S37: =$S$3 -> 1 | T37: =(Q37/(R37*S37))/12 -> 54.580836
A38: Year 30 | B38: 2054 | C38: =C37*(1-$C$5) -> 0.0729 | D38: 4000 | E38: =D38*C38*1000000000 -> 2.916e+11 | F38: =E38*(1-$F$3) -> 2.90142e+11 | G38: =G37+$H$5 -> 0.69 | H38: =F38*G38 -> 2.0019798e+11 | I38: =I37+H38 -> 1.0080686e+14 | J38: =(J37+H38)*(1-$J$3) -> 1.0016619e+14 | K38: =J37*$K$3 -> 6.3410206e+12 | L38: =F38*(1-G38) -> 8.994402e+10 | M38: =K38+L38 -> 6.4309646e+12 | O38: =(M38-N38)*(1-$O$3) -> 6.3988097e+12 | Q38: =O38-P38 -> 6.3988097e+12 | R38: 9813251659 | S38: =$S$3 -> 1 | T38: =(Q38/(R38*S38))/12 -> 54.338171
A39: Year 31 | B39: 2055 | C39: =C38*(1-$C$5) -> 0.06561 | D39: 4000 | E39: =D39*C39*1000000000 -> 2.6244e+11 | F39: =E39*(1-$F$3) -> 2.611278e+11 | G39: =G38+$H$5 -> 0.71 | H39: =F39*G39 -> 1.8540074e+11 | I39: =I38+H39 -> 1.0099226e+14 | J39: =(J38+H39)*(1-$J$3) -> 1.0030141e+14 | K39: =J38*$K$3 -> 6.3505362e+12 | L39: =F39*(1-G39) -> 7.5727062e+10 | M39: =K39+L39 -> 6.4262633e+12 | O39: =(M39-N39)*(1-$O$3) -> 6.394132e+12 | Q39: =O39-P39 -> 6.394132e+12 | R39: 9846237570 | S39: =$S$3 -> 1 | T39: =(Q39/(R39*S39))/12 -> 54.116542
A40: Year 32 | B40: 2056 | C40: =C39*(1-$C$5) -> 0.059049 | D40: 4000 | E40: =D40*C40*1000000000 -> 2.36196e+11 | F40: =E40*(1-$F$3) -> 2.3501502e+11 | G40: =G39+$H$5 -> 0.73 | H40: =F40*G40 -> 1.7156096e+11 | I40: =I39+H40 -> 1.0116382e+14 | J40: =(J39+H40)*(1-$J$3) -> 1.0042274e+14 | K40: =J39*$K$3 -> 6.3591095e+12 | L40: =F40*(1-G40) -> 6.3454055e+10 | M40: =K40+L40 -> 6.4225636e+12 | O40: =(M40-N40)*(1-$O$3) -> 6.3904507e+12 | Q40: =O40-P40 -> 6.3904507e+12 | R40: 9877680392 | S40: =$S$3 -> 1 | T40: =(Q40/(R40*S40))/12 -> 53.913221
A41: Year 33 | B41: 2057 | C41: =C40*(1-$C$5) -> 0.0531441 | D41: 4000 | E41: =D41*C41*1000000000 -> 2.125764e+11 | F41: =E41*(1-$F$3) -> 2.1151352e+11 | G41: =G40+$H$5 -> 0.75 | H41: =F41*G41 -> 1.5863514e+11 | I41: =I40+H41 -> 1.0132245e+14 | J41: =(J40+H41)*(1-$J$3) -> 1.0053108e+14 | K41: =J40*$K$3 -> 6.3668015e+12 | L41: =F41*(1-G41) -> 5.2878379e+10 | M41: =K41+L41 -> 6.4196799e+12 | N41: =M41*0% -> 0 | O41: =(M41-N41)*(1-$O$3) -> 6.3875815e+12 | Q41: =O41-P41 -> 6.3875815e+12 | R41: 9907637193 | S41: =$S$3 -> 1 | T41: =(Q41/(R41*S41))/12 -> 53.726075
A42: Year 34 | B42: 2058 | C42: =C41*(1-$C$5) -> 0.04782969 | D42: 4000 | E42: =D42*C42*1000000000 -> 1.9131876e+11 | F42: =E42*(1-$F$3) -> 1.9036217e+11 | G42: =G41+$H$5 -> 0.77 | H42: =F42*G42 -> 1.4657887e+11 | I42: =I41+H42 -> 1.0146903e+14 | J42: =(J41+H42)*(1-$J$3) -> 1.0062732e+14 | K42: =J41*$K$3 -> 6.3736705e+12 | L42: =F42*(1-G42) -> 4.3783298e+10 | M42: =K42+L42 -> 6.4174538e+12 | N42: =M42*0.4% -> 2.5669815e+10 | O42: =(M42-N42)*(1-$O$3) -> 6.3598251e+12 | Q42: =O42-P42 -> 6.3598251e+12 | R42: 9936164379 | S42: =$S$3 -> 1 | T42: =(Q42/(R42*S42))/12 -> 53.339035
...

Sheet Carbon charge rates
F1: Charge based on country income group - smaller jumps
A2: CVI rank | B2: Country | C2: CVI index score | D2: Discount applied to carbon charge for CVI score | E2: Income group | F2: Average GNI per capita for this income group | G2: Income group index multiplier | H2: Carbon charge start point (no discounts) | I2: Carbon charge start point with CVI discounts | J2: Annual emissions (Mt CO2e) | K2: Carbon charge raised in Year 1
A3: 1 | B3: Switzerland | C3: 0.251 | D3: 0 | E3: High | F3: 48441 | G3: =F3/1000 -> 48.441 | H3: 240 | I3: =H3*(1-D3) -> 240 | J3: 34.2 | K3: =I3*J3*1000000 -> 8208000000
A4: 2 | B4: Czech Republic | C4: 0.263 | D4: 0 | E4: High | F4: 48441 | G4: =F4/1000 -> 48.441 | H4: 240 | I4: =H4*(1-D4) -> 240 | J4: 90.5 | K4: =I4*J4*1000000 -> 21720000000
A5: 3 | B5: Norway | C5: 0.27 | D5: 0 | E5: High | F5: 48441 | G5: =F5/1000 -> 48.441 | H5: 240 | I5: =H5*(1-D5) -> 240 | J5: 44.1 | K5: =I5*J5*1000000 -> 10584000000
A6: 4 | B6: Canada | C6: 0.281 | D6: 0 | E6: High | F6: 48441 | G6: =F6/1000 -> 48.441 | H6: 240 | I6: =H6*(1-D6) -> 240 | J6: 575 | K6: =I6*J6*1000000 -> 138000000000
A7: 5 | B7: United Kingdom | C7: 0.285 | D7: 0 | E7: High | F7: 48441 | G7: =F7/1000 -> 48.441 | H7: 240 | I7: =H7*(1-D7) -> 240 | J7: 302.1 | K7: =I7*J7*1000000 -> 72504000000
A8: 6 | B8: Spain | C8: 0.292 | D8: 0 | E8: High | F8: 48441 | G8: =F8/1000 -> 48.441 | H8: 240 | I8: =H8*(1-D8) -> 240 | J8: 217.3 | K8: =I8*J8*1000000 -> 52152000000
A9: 6 | B9: Israel | C9: 0.292 | D9: 0 | E9: High | F9: 48441 | G9: =F9/1000 -> 48.441 | H9: 240 | I9: =H9*(1-D9) -> 240 | J9: 61.3 | K9: =I9*J9*1000000 -> 14712000000
A10: 8 | B10: Finland | C10: 0.295 | D10: 0 | E10: High | F10: 48441 | G10: =F10/1000 -> 48.441 | H10: 240 | I10: =H10*(1-D10) -> 240 | J10: 32.3 | K10: =I10*J10*1000000 -> 7.752e+09
A11: 9 | B11: United States | C11: 0.298 | D11: 0 | E11: High | F11: 48441 | G11: =F11/1000 -> 48.441 | H11: 240 | I11: =H11*(1-D11) -> 240 | J11: 4682 | K11: =I11*J11*1000000 -> 1123680000000
A12: 10 | B12: Austria | C12: 0.299 | D12: 0 | E12: High | F12: 48441 | G12: =F12/1000 -> 48.441 | H12: 240 | I12: =H12*(1-D12) -> 240 | J12: 58.8 | K12: =I12*J12*1000000 -> 14112000000
A13: 10 | B13: Germany | C13: 0.299 | D13: 0 | E13: High | F13: 48441 | G13: =F13/1000 -> 48.441 | H13: 240 | I13: =H13*(1-D13) -> 240 | J13: 583 | K13: =I13*J13*1000000 -> 139920000000
A14: 12 | B14: France | C14: 0.3 | D14: 0 | E14: High | F14: 48441 | G14: =F14/1000 -> 48.441 | H14: 240 | I14: =H14*(1-D14) -> 240 | J14: 282.4 | K14: =I14*J14*1000000 -> 67776000000
... A19: 17 | B19: Slovenia | C19: 0.315 | D19: 0 | E19: High | F19: 48441 | G19: =F19/1000 -> 48.441 | H19: 240 | I19: =H19*(1-D19) -> 240 | J19: 12.1 | K19: =I19*J19*1000000 -> 2904000000
A20: 18 | B20: Kazakhstan | C20: 0.316 | D20: 0 | E20: Upper middle | F20: 10563 | G20: 24 | H20: =G20*5 -> 120 | I20: =H20*(1-D20) -> 120 | J20: 239.9 | K20: =I20*J20*1000000 -> 28788000000
A21: 19 | B21: Malta | C21: 0.318 | D21: 0 | E21: High | F21: 48441 | G21: =F21/1000 -> 48.441 | H21: 240 | I21: =H21*(1-D21) -> 240 | J21: 1.7 | K21: =I21*J21*1000000 -> 408000000
A22: 20 | B22: Portugal | C22: 0.319 | D22: 0 | E22: High | F22: 48441 | G22: =F22/1000 -> 48.441 | H22: 240 | I22: =H22*(1-D22) -> 240 | J22: 36.2 | K22: =I22*J22*1000000 -> 8688000000
A23: 21 | B23: New Zealand | C23: 0.321 | D23: 0 | E23: High | F23: 48441 | G23: =F23/1000 -> 48.441 | H23: 240 | I23: =H23*(1-D23) -> 240 | J23: 35.8 | K23: =I23*J23*1000000 -> 8592000000
A24: 22 | B24: Kyrgyzstan | C24: 0.323 | D24: 0 | E24: Lower middle | F24: 2511 | G24: 12 | H24: =G24*5 -> 60 | I24: =H24*(1-D24) -> 60 | J24: 10.5 | K24: =I24*J24*1000000 -> 630000000
A25: 22 | B25: Russian Federation | C25: 0.323 | D25: 0 | E25: High | F25: 48441 | G25: =F25/1000 -> 48.441 | H25: 240 | I25: =H25*(1-D25) -> 240 | J25: 2069.5 | K25: =I25*J25*1000000 -> 496680000000
A26: 24 | B26: Sweden | C26: 0.324 | D26: 0 | E26: High | F26: 48441 | G26: =F26/1000 -> 48.441 | H26: 240 | I26: =H26*(1-D26) -> 240 | J26: 35.4 | K26: =I26*J26*1000000 -> 8496000000
A27: 25 | B27: Belarus | C27: 0.325 | D27: 0 | E27: Upper middle | F27: 10563 | G27: 24 | H27: =G27*5 -> 120 | I27: =H27*(1-D27) -> 120 | J27: 54.2 | K27: =I27*J27*1000000 -> 6504000000
A28: 26 | B28: Belgium | C28: 0.329 | D28: 0 | E28: High | F28: 48441 | G28: =F28/1000 -> 48.441 | H28: 240 | I28: =H28*(1-D28) -> 240 | J28: 84.3 | K28: =I28*J28*1000000 -> 20232000000
A29: 27 | B29: Estonia | C29: 0.33 | D29: 0 | E29: High | F29: 48441 | G29: =F29/1000 -> 48.441 | H29: 240 | I29: =H29*(1-D29) -> 240 | J29: 11.4 | K29: =I29*J29*1000000 -> 2736000000
A30: 28 | B30: Chile | C30: 0.334 | D30: 0 | E30: High | F30: 48441 | G30: =F30/1000 -> 48.441 | H30: 240 | I30: =H30*(1-D30) -> 240 | J30: 84 | K30: =I30*J30*1000000 -> 20160000000
A31: 29 | B31: Greece | C31: 0.339 | D31: 0 | E31: High | F31: 48441 | G31: =F31/1000 -> 48.441 | H31: 240 | I31: =H31*(1-D31) -> 240 | J31: 51.7 | K31: =I31*J31*1000000 -> 12408000000
A32: 30 | B32: Italy | C32: 0.341 | D32: 0 | E32: High | F32: 48441 | G32: =F32/1000 -> 48.441 | H32: 240 | I32: =H32*(1-D32) -> 240 | J32: 305.5 | K32: =I32*J32*1000000 -> 73320000000
A33: 30 | B33: Mongolia | C33: 0.341 | D33: 0 | E33: Upper middle | F33: 10563 | G33: 24 | H33: =G33*5 -> 120 | I33: =H33*(1-D33) -> 120 | J33: 28.1 | K33: =I33*J33*1000000 -> 3372000000
A34: 32 | B34: Slovakia | C34: 0.347 | D34: 0 | E34: High | F34: 48441 | G34: =F34/1000 -> 48.441 | H34: 240 | I34: =H34*(1-D34) -> 240 | J34: 34.9 | K34: =I34*J34*1000000 -> 8376000000
A35: 33 | B35: Denmark | C35: 0.348 | D35: 0 | E35: High | F35: 48441 | G35: =F35/1000 -> 48.441 | H35: 240 | I35: =H35*(1-D35) -> 240 | J35: 26.8 | K35: =I35*J35*1000000 -> 6432000000
A36: 33 | B36: Iceland | C36: 0.348 | D36: 0 | E36: High | F36: 48441 | G36: =F36/1000 -> 48.441 | H36: 240 | I36: =H36*(1-D36) -> 240 | J36: 3.1 | K36: =I36*J36*1000000 -> 744000000
A37: 35 | B37: Bosnia & Herzegovina | C37: 0.349 | D37: 0 | E37: Upper middle | F37: 10563 | G37: 24 | H37: =G37*5 -> 120 | I37: =H37*(1-D37) -> 120 | J37: 22 | K37: =I37*J37*1000000 -> 2640000000
A38: 35 | B38: Uzbekistan | C38: 0.349 | D38: 0 | E38: Lower middle | F38: 2511 | G38: 12 | H38: =G38*5 -> 60 | I38: =H38*(1-D38) -> 60 | J38: 137.9 | K38: =I38*J38*1000000 -> 8274000000
A39: 37 | B39: Hungary | C39: 0.352 | D39: 0.1 | E39: High | F39: 48441 | G39: =F39/1000 -> 48.441 | H39: 240 | I39: =H39*(1-D39) -> 216 | J39: 43.8 | K39: =I39*J39*1000000 -> 9460800000
A40: 37 | B40: Qatar | C40: 0.352 | D40: 0.1 | E40: High | F40: 48441 | G40: =F40/1000 -> 48.441 | H40: 240 | I40: =H40*(1-D40) -> 216 | J40: 127.9 | K40: =I40*J40*1000000 -> 27626400000
A41: 39 | B41: China | C41: 0.353 | D41: 0.1 | E41: Upper middle | F41: 10563 | G41: 24 | H41: =G41*5 -> 120 | I41: =H41*(1-D41) -> 108 | J41: 13259.6 | K41: =I41*J41*1000000 -> 1432036800000
A42: 39 | B42: Republic of Korea | C42: 0.353 | D42: 0.1 | E42: High | F42: 48441 | G42: =F42/1000 -> 48.441 | H42: 240 | I42: =H42*(1-D42) -> 216 | J42: 573.5 | K42: =I42*J42*1000000 -> 123876000000
A43: 41 | B43: Netherlands | C43: 0.355 | D43: 0.1 | E43: High | F43: 48441 | G43: =F43/1000 -> 48.441 | H43: 240 | I43: =H43*(1-D43) -> 216 | J43: 122.9 | K43: =I43*J43*1000000 -> 26546400000
A44: 42 | B44: Bulgaria | C44: 0.358 | D44: 0.1 | E44: High | F44: 48441 | G44: =F44/1000 -> 48.441 | H44: 240 | I44: =H44*(1-D44) -> 216 | J44: 39.8 | K44: =I44*J44*1000000 -> 8596800000
...

Sheet Malawi Norway summary
B3: 2025 | C3: 2030 | D3: 2035 | E3: 2040 | F3: 2063
A4: MALAWI ONLY
A5: Fund capital available for Malawi | B5: ='Malawi-only'!$L$9 -> 4400673.6 | C5: ='Malawi-only'!$L$14 -> 1.1353063e+08 | D5: ='Malawi-only'!$L$19 -> 7.3480518e+08 | E5: ='Malawi-only'!$L$24 -> 4.7725949e+09 | F5: ='Malawi-only'!$L$47 -> 5.7905474e+10
A6: Number of solar farms it would fund | B6: =B5/65000000 -> 0.06770267 | C6: =C5/65000000 -> 1.7466251 | D6: =D5/65000000 -> 11.304695 | E6: =E5/65000000 -> 73.424537 | F6: =F5/65000000 -> 890.85345
A7: Climate grants this year in Malawi | B7: ='Malawi-only'!$R$9 -> 19713873 | C7: ='Malawi-only'!$R$14 -> 1.1782011e+08 | D7: ='Malawi-only'!$R$19 -> 3.813143e+08 | E7: ='Malawi-only'!$R$24 -> 8.3758836e+08 | F7: ='Malawi-only'!$R$47 -> 1.7681201e+09
A8: Monthly cash transfer per person | B8: ='Malawi-only'!$V$9 -> 0.073947329 | C8: ='Malawi-only'!$V$14 -> 0.42453984 | D8: ='Malawi-only'!$V$19 -> 1.3251068 | E8: ='Malawi-only'!$V$24 -> 2.8180999 | F8: ='Malawi-only'!$V$47 -> 5.426895
A9: Monthly cash per four-person household | B9: =B8*4 -> 0.29578932 | C9: =C8*4 -> 1.6981594 | D9: =D8*4 -> 5.3004271 | E9: =E8*4 -> 11.2724 | F9: =F8*4 -> 21.70758
A10: MALAWI and MINIMAL NORWAY
A11: Fund capital available for Malawi | B11: ='Malawi and Norway'!$L$9 -> 2.8330189e+09 | C11: ='Malawi and Norway'!$L$14 -> 1.3333037e+10 | D11: ='Malawi and Norway'!$L$19 -> 1.6840344e+10 | E11: ='Malawi and Norway'!$L$24 -> 2.083791e+10 | F11: ='Malawi and Norway'!$L$47 -> 7.3843519e+10
A12: Number of solar farms it would fund | B12: =B11/65000000 -> 43.584906 | C12: =C11/65000000 -> 205.12364 | D12: =D11/65000000 -> 259.08222 | E12: =E11/65000000 -> 320.58323 | F12: =F11/65000000 -> 1136.0541
A13: Climate grants this year in Malawi | B13: ='Malawi and Norway'!$R$9 -> 19713873 | C13: ='Malawi and Norway'!$R$14 -> 4.8652348e+08 | D13: ='Malawi and Norway'!$R$19 -> 8.8956128e+08 | E13: ='Malawi and Norway'!$R$24 -> 1.344566e+09 | F13: ='Malawi and Norway'!$R$47 -> 2.2625952e+09
A14: Monthly cash transfer per person | B14: ='Malawi and Norway'!$V$9 -> 0.073947329 | C14: ='Malawi and Norway'!$V$14 -> 1.7530844 | D14: ='Malawi and Norway'!$V$19 -> 3.0913178 | E14: ='Malawi and Norway'!$V$24 -> 4.5238467 | F14: ='Malawi and Norway'!$V$47 -> 6.9445887
A15: Monthly cash per four-person household | B15: =B14*4 -> 0.29578932 | C15: =C14*4 -> 7.0123375 | D15: =D14*4 -> 12.365271 | E15: =E14*4 -> 18.095387 | F15: =F14*4 -> 27.778355
A16: MALAWI and FULL NORWAY
A17: Fund capital available for Malawi | B17: ='Malawi and Norway'!$X$9 -> 1.8621261e+09 | C17: ='Malawi and Norway'!$X$14 -> 1.0068088e+10 | D17: ='Malawi and Norway'!$X$19 -> 1.6259368e+10 | E17: ='Malawi and Norway'!$X$24 -> 2.9265276e+10 | F17: ='Malawi and Norway'!$X$47 -> 1.2085918e+11
A18: Number of solar farms it would fund | B18: =B17/65000000 -> 28.648094 | C18: =C17/65000000 -> 154.89366 | D18: =D17/65000000 -> 250.14412 | E18: =E17/65000000 -> 450.23501 | F18: =F17/65000000 -> 1859.372
A19: Climate grants this year in Malawi | B19: ='Malawi and Norway'!$Z$9 -> 4.091063e+08 | C19: ='Malawi and Norway'!$Z$14 -> 6.5054613e+08 | D19: ='Malawi and Norway'!$Z$19 -> 8.5414993e+08 | E19: ='Malawi and Norway'!$Z$24 -> 1.0832393e+09 | F19: ='Malawi and Norway'!$Z$47 -> 1.6468298e+09
A20: Monthly cash transfer per person | B20: ='Malawi and Norway'!$AA$9 -> 21.570917 | C20: ='Malawi and Norway'!$AA$14 -> 22.479488 | D20: ='Malawi and Norway'!$AA$19 -> 22.901569 | E20: ='Malawi and Norway'!$AA$24 -> 23.471304 | F20: ='Malawi and Norway'!$AA$47 -> 28.270853
A21: Monthly cash per four-person household | B21: =B20*4 -> 86.283666 | C21: =C20*4 -> 89.917953 | D21: =D20*4 -> 91.606275 | E21: =E20*4 -> 93.885216 | F21: =F20*4 -> 113.08341
B25: 2025 | C25: 2030 | D25: 2035 | E25: 2040 | F25: 2063
A26: MALAWI ONLY
A27: Monthly cash transfer per person | B27: ='Malawi-only'!$V$9 -> 0.073947329 | C27: ='Malawi-only'!$V$14 -> 0.42453984 | D27: ='Malawi-only'!$V$19 -> 1.3251068 | E27: ='Malawi-only'!$V$24 -> 2.8180999 | F27: ='Malawi-only'!$V$47 -> 5.426895
A28: Monthly cash per four-person household | B28: =B27*4 -> 0.29578932 | C28: =C27*4 -> 1.6981594 | D28: =D27*4 -> 5.3004271 | E28: =E27*4 -> 11.2724 | F28: =F27*4 -> 21.70758
A29: MALAWI and MINIMAL NORWAY
A30: Monthly cash transfer per person | B30: ='Malawi and Norway'!$V$9 -> 0.073947329 | C30: ='Malawi and Norway'!$V$14 -> 1.7530844 | D30: ='Malawi and Norway'!$V$19 -> 3.0913178 | E30: ='Malawi and Norway'!$V$24 -> 4.5238467 | F30: ='Malawi and Norway'!$V$47 -> 6.9445887
A31: Monthly cash per four-person household | B31: =B30*4 -> 0.29578932 | C31: =C30*4 -> 7.0123375 | D31: =D30*4 -> 12.365271 | E31: =E30*4 -> 18.095387 | F31: =F30*4 -> 27.778355
A32: MALAWI and FULL NORWAY
A33: Monthly cash transfer per person | B33: ='Malawi and Norway'!$AA$9 -> 21.570917 | C33: ='Malawi and Norway'!$AA$14 -> 22.479488 | D33: ='Malawi and Norway'!$AA$19 -> 22.901569 | E33: ='Malawi and Norway'!$AA$24 -> 23.471304 | F33: ='Malawi and Norway'!$AA$47 -> 28.270853
A34: Monthly cash per four-person household | B34: =B33*4 -> 86.283666 | C34: =C33*4 -> 89.917953 | D34: =D33*4 -> 91.606275 | E34: =E33*4 -> 93.885216 | F34: =F33*4 -> 113.08341
B37: 2025 | C37: 2030 | D37: 2035 | E37: 2040 | F37: 2063
A38: MALAWI ONLY
A39: Fund capital available for Malawi | B39: ='Malawi-only'!$L$9 -> 4400673.6 | C39: ='Malawi-only'!$L$14 -> 1.1353063e+08 | D39: ='Malawi-only'!$L$19 -> 7.3480518e+08 | E39: ='Malawi-only'!$L$24 -> 4.7725949e+09 | F39: ='Malawi-only'!$L$47 -> 5.7905474e+10
A40: Number of solar farms it would fund | B40: =B39/65000000 -> 0.06770267 | C40: =C39/65000000 -> 1.7466251 | D40: =D39/65000000 -> 11.304695 | E40: =E39/65000000 -> 73.424537 | F40: =F39/65000000 -> 890.85345
A41: MALAWI and MINIMAL NORWAY
A42: Fund capital available for Malawi | B42: ='Malawi and Norway'!$L$9 -> 2.8330189e+09 | C42: ='Malawi and Norway'!$L$14 -> 1.3333037e+10 | D42: ='Malawi and Norway'!$L$19 -> 1.6840344e+10 | E42: ='Malawi and Norway'!$L$24 -> 2.083791e+10 | F42: ='Malawi and Norway'!$L$47 -> 7.3843519e+10
A43: Number of solar farms it would fund | B43: =B42/65000000 -> 43.584906 | C43: =C42/65000000 -> 205.12364 | D43: =D42/65000000 -> 259.08222 | E43: =E42/65000000 -> 320.58323 | F43: =F42/65000000 -> 1136.0541
A44: MALAWI and FULL NORWAY
A45: Fund capital available for Malawi | B45: ='Malawi and Norway'!$X$9 -> 1.8621261e+09 | C45: ='Malawi and Norway'!$X$14 -> 1.0068088e+10 | D45: ='Malawi and Norway'!$X$19 -> 1.6259368e+10 | E45: ='Malawi and Norway'!$X$24 -> 2.9265276e+10 | F45: ='Malawi and Norway'!$X$47 -> 1.2085918e+11
A46: Number of solar farms it would fund | B46: =B45/65000000 -> 28.648094 | C46: =C45/65000000 -> 154.89366 | D46: =D45/65000000 -> 250.14412 | E46: =E45/65000000 -> 450.23501 | F46: =F45/65000000 -> 1859.372
B49: 2025 | C49: 2030 | D49: 2035 | E49: 2040 | F49: 2063
...

Sheet Malawi-only
A1: National scenarios, adapted from Scenario 1 - Malawi
A2: Population of Malawi (in 2025) | B2: Global population in 2025 | C2: Initial fossil fuel extraction cap (gigatonnes of CO2e) | D2: Expected national allowance price per tonne of CO2 | E2: Assumed starting rate of compensation for extra national allowances per gigatonne of CO2 | F2: Initial carbon charge (per extracted tonne of CO2e) | H2: Running costs of Trust (% of charge money raised) | I2: Initial proportion of charge proceeds going into the Fund (% of total proceeds) | K2: Malawi's cumulative carbon emissions | L2: Management costs of the Fund (% of total Fund capital expended) | M2: Assumed annual rate of return on Fund investments | N2: Initial proportion of charge proceeds directly distributed as dividends that year (% of total proceeds) | P2: Year that money from distribution pot starts getting reinvested | Q2: Distribution costs of the pot (% of total distributed) | T2: Initial global population expected in 2025 | U2: Proportion of global population to receive dividends
